/usr/lib/python3/dist-packages/requests/__init__.py:89: RequestsDependencyWarning: urllib3 (1.26.8) or chardet (3.0.4) doesn't match a supported version!
  warnings.warn("urllib3 ({}) or chardet ({}) doesn't match a supported "
Traceback (most recent call last):
  File "sess_scraper.py", line 11, in <module>
    from webdriver_manager.chrome import ChromeDriverManager
ModuleNotFoundError: No module named 'webdriver_manager'
/usr/lib/python3/dist-packages/requests/__init__.py:89: RequestsDependencyWarning: urllib3 (1.26.8) or chardet (3.0.4) doesn't match a supported version!
  warnings.warn("urllib3 ({}) or chardet ({}) doesn't match a supported "
Traceback (most recent call last):
  File "sess_scraper.py", line 15, in <module>
    from bs4 import BeautifulSoup as bs
ModuleNotFoundError: No module named 'bs4'
/usr/lib/python3/dist-packages/requests/__init__.py:89: RequestsDependencyWarning: urllib3 (1.26.8) or chardet (3.0.4) doesn't match a supported version!
  warnings.warn("urllib3 ({}) or chardet ({}) doesn't match a supported "
Traceback (most recent call last):
  File "/home/ubuntu/.local/lib/python3.8/site-packages/selenium/webdriver/common/service.py", line 71, in start
    self.process = subprocess.Popen(cmd, env=self.env,
  File "/usr/lib/python3.8/subprocess.py", line 858, in __init__
    self._execute_child(args, executable, preexec_fn, close_fds,
  File "/usr/lib/python3.8/subprocess.py", line 1704, in _execute_child
    raise child_exception_type(errno_num, err_msg, err_filename)
FileNotFoundError: [Errno 2] No such file or directory: 'geckodriver.exe'

During handling of the above exception, another exception occurred:

Traceback (most recent call last):
  File "sess_scraper.py", line 37, in <module>
    driver = webdriver.Firefox(service=s,options=options)
  File "/home/ubuntu/.local/lib/python3.8/site-packages/selenium/webdriver/firefox/webdriver.py", line 174, in __init__
    self.service.start()
  File "/home/ubuntu/.local/lib/python3.8/site-packages/selenium/webdriver/common/service.py", line 81, in start
    raise WebDriverException(
selenium.common.exceptions.WebDriverException: Message: 'geckodriver.exe' executable needs to be in PATH. Please see https://chromedriver.chromium.org/home

/usr/lib/python3/dist-packages/requests/__init__.py:89: RequestsDependencyWarning: urllib3 (1.26.8) or chardet (3.0.4) doesn't match a supported version!
  warnings.warn("urllib3 ({}) or chardet ({}) doesn't match a supported "
Traceback (most recent call last):
  File "/home/ubuntu/.local/lib/python3.8/site-packages/selenium/webdriver/common/service.py", line 71, in start
    self.process = subprocess.Popen(cmd, env=self.env,
  File "/usr/lib/python3.8/subprocess.py", line 858, in __init__
    self._execute_child(args, executable, preexec_fn, close_fds,
  File "/usr/lib/python3.8/subprocess.py", line 1704, in _execute_child
    raise child_exception_type(errno_num, err_msg, err_filename)
FileNotFoundError: [Errno 2] No such file or directory: 'geckodriver.exe'

During handling of the above exception, another exception occurred:

Traceback (most recent call last):
  File "sess_scraper.py", line 37, in <module>
    driver = webdriver.Firefox(service=s,options=options)
  File "/home/ubuntu/.local/lib/python3.8/site-packages/selenium/webdriver/firefox/webdriver.py", line 174, in __init__
    self.service.start()
  File "/home/ubuntu/.local/lib/python3.8/site-packages/selenium/webdriver/common/service.py", line 81, in start
    raise WebDriverException(
selenium.common.exceptions.WebDriverException: Message: 'geckodriver.exe' executable needs to be in PATH. Please see https://chromedriver.chromium.org/home

/usr/lib/python3/dist-packages/requests/__init__.py:89: RequestsDependencyWarning: urllib3 (1.26.8) or chardet (3.0.4) doesn't match a supported version!
  warnings.warn("urllib3 ({}) or chardet ({}) doesn't match a supported "
Traceback (most recent call last):
  File "/home/ubuntu/.local/lib/python3.8/site-packages/selenium/webdriver/common/service.py", line 71, in start
    self.process = subprocess.Popen(cmd, env=self.env,
  File "/usr/lib/python3.8/subprocess.py", line 858, in __init__
    self._execute_child(args, executable, preexec_fn, close_fds,
  File "/usr/lib/python3.8/subprocess.py", line 1704, in _execute_child
    raise child_exception_type(errno_num, err_msg, err_filename)
FileNotFoundError: [Errno 2] No such file or directory: 'geckodriver.exe'

During handling of the above exception, another exception occurred:

Traceback (most recent call last):
  File "sess_scraper.py", line 37, in <module>
    driver = webdriver.Firefox(service=s,options=options)
  File "/home/ubuntu/.local/lib/python3.8/site-packages/selenium/webdriver/firefox/webdriver.py", line 174, in __init__
    self.service.start()
  File "/home/ubuntu/.local/lib/python3.8/site-packages/selenium/webdriver/common/service.py", line 81, in start
    raise WebDriverException(
selenium.common.exceptions.WebDriverException: Message: 'geckodriver.exe' executable needs to be in PATH. Please see https://chromedriver.chromium.org/home

/usr/lib/python3/dist-packages/requests/__init__.py:89: RequestsDependencyWarning: urllib3 (1.26.8) or chardet (3.0.4) doesn't match a supported version!
  warnings.warn("urllib3 ({}) or chardet ({}) doesn't match a supported "
Traceback (most recent call last):
  File "/home/ubuntu/.local/lib/python3.8/site-packages/selenium/webdriver/common/service.py", line 71, in start
    self.process = subprocess.Popen(cmd, env=self.env,
  File "/usr/lib/python3.8/subprocess.py", line 858, in __init__
    self._execute_child(args, executable, preexec_fn, close_fds,
  File "/usr/lib/python3.8/subprocess.py", line 1704, in _execute_child
    raise child_exception_type(errno_num, err_msg, err_filename)
FileNotFoundError: [Errno 2] No such file or directory: 'geckodriver.exe'

During handling of the above exception, another exception occurred:

Traceback (most recent call last):
  File "sess_scraper.py", line 37, in <module>
    driver = webdriver.Firefox(service=s,options=options)
  File "/home/ubuntu/.local/lib/python3.8/site-packages/selenium/webdriver/firefox/webdriver.py", line 174, in __init__
    self.service.start()
  File "/home/ubuntu/.local/lib/python3.8/site-packages/selenium/webdriver/common/service.py", line 81, in start
    raise WebDriverException(
selenium.common.exceptions.WebDriverException: Message: 'geckodriver.exe' executable needs to be in PATH. Please see https://chromedriver.chromium.org/home

